ERROR 2025-07-04 02:48:31,383 log 9656 11360 Internal Server Error: /api/v1/email/signup/verification/
Traceback (most recent call last):
  File "B:\Github\django-unchained\.venv\Lib\site-packages\django\core\handlers\exception.py", line 55, in inner
    response = get_response(request)
  File "B:\Github\django-unchained\.venv\Lib\site-packages\django\core\handlers\base.py", line 197, in _get_response
    response = wrapped_callback(request, *callback_args, **callback_kwargs)
  File "B:\Github\django-unchained\core\views.py", line 6, in index
    return render(request, 'index.html')
  File "B:\Github\django-unchained\.venv\Lib\site-packages\django\shortcuts.py", line 25, in render
    content = loader.render_to_string(template_name, context, request, using=using)
  File "B:\Github\django-unchained\.venv\Lib\site-packages\django\template\loader.py", line 61, in render_to_string
    template = get_template(template_name, using=using)
  File "B:\Github\django-unchained\.venv\Lib\site-packages\django\template\loader.py", line 19, in get_template
    raise TemplateDoesNotExist(template_name, chain=chain)
django.template.exceptions.TemplateDoesNotExist: index.html
ERROR 2025-07-04 02:55:00,130 log 8328 13040 Internal Server Error: /api/v1/email/signup/verification/
Traceback (most recent call last):
  File "B:\Github\django-unchained\.venv\Lib\site-packages\django\core\handlers\exception.py", line 55, in inner
    response = get_response(request)
  File "B:\Github\django-unchained\.venv\Lib\site-packages\django\core\handlers\base.py", line 197, in _get_response
    response = wrapped_callback(request, *callback_args, **callback_kwargs)
  File "B:\Github\django-unchained\core\views.py", line 6, in index
    return render(request, 'index.html')
  File "B:\Github\django-unchained\.venv\Lib\site-packages\django\shortcuts.py", line 25, in render
    content = loader.render_to_string(template_name, context, request, using=using)
  File "B:\Github\django-unchained\.venv\Lib\site-packages\django\template\loader.py", line 61, in render_to_string
    template = get_template(template_name, using=using)
  File "B:\Github\django-unchained\.venv\Lib\site-packages\django\template\loader.py", line 19, in get_template
    raise TemplateDoesNotExist(template_name, chain=chain)
django.template.exceptions.TemplateDoesNotExist: index.html
ERROR 2025-07-04 02:59:25,750 log 17876 9312 Internal Server Error: /api/v1/email/signup/verification/
Traceback (most recent call last):
  File "B:\Github\django-unchained\.venv\Lib\site-packages\rest_framework\views.py", line 512, in dispatch
    response = handler(request, *args, **kwargs)
  File "B:\Github\django-unchained\.venv\Lib\site-packages\rest_framework\views.py", line 173, in http_method_not_allowed
    raise exceptions.MethodNotAllowed(request.method)
rest_framework.exceptions.MethodNotAllowed: Method "PUT" not allowed.

During handling of the above exception, another exception occurred:

Traceback (most recent call last):
  File "B:\Github\django-unchained\.venv\Lib\site-packages\rest_framework\settings.py", line 179, in import_from_string
    return import_string(val)
  File "B:\Github\django-unchained\.venv\Lib\site-packages\django\utils\module_loading.py", line 30, in import_string
    return cached_import(module_path, class_name)
  File "B:\Github\django-unchained\.venv\Lib\site-packages\django\utils\module_loading.py", line 15, in cached_import
    module = import_module(module_path)
  File "C:\Users\Ankit\AppData\Local\Programs\Python\Python313\Lib\importlib\__init__.py", line 88, in import_module
    return _bootstrap._gcd_import(name[level:], package, level)
           ~~~~~~~~~~~~~~~~~~~~~~^^^^^^^^^^^^^^^^^^^^^^^^^^^^^^
  File "<frozen importlib._bootstrap>", line 1387, in _gcd_import
  File "<frozen importlib._bootstrap>", line 1360, in _find_and_load
  File "<frozen importlib._bootstrap>", line 1324, in _find_and_load_unlocked
ModuleNotFoundError: No module named 'api.resources.exception_handler'

During handling of the above exception, another exception occurred:

Traceback (most recent call last):
  File "B:\Github\django-unchained\.venv\Lib\site-packages\django\core\handlers\exception.py", line 55, in inner
    response = get_response(request)
  File "B:\Github\django-unchained\.venv\Lib\site-packages\django\core\handlers\base.py", line 197, in _get_response
    response = wrapped_callback(request, *callback_args, **callback_kwargs)
  File "B:\Github\django-unchained\.venv\Lib\site-packages\django\views\decorators\csrf.py", line 65, in _view_wrapper
    return view_func(request, *args, **kwargs)
  File "B:\Github\django-unchained\.venv\Lib\site-packages\django\views\generic\base.py", line 105, in view
    return self.dispatch(request, *args, **kwargs)
           ~~~~~~~~~~~~~^^^^^^^^^^^^^^^^^^^^^^^^^^
  File "B:\Github\django-unchained\.venv\Lib\site-packages\rest_framework\views.py", line 515, in dispatch
    response = self.handle_exception(exc)
  File "B:\Github\django-unchained\.venv\Lib\site-packages\rest_framework\views.py", line 469, in handle_exception
    exception_handler = self.get_exception_handler()
  File "B:\Github\django-unchained\.venv\Lib\site-packages\rest_framework\views.py", line 304, in get_exception_handler
    return self.settings.EXCEPTION_HANDLER
           ^^^^^^^^^^^^^^^^^^^^^^^^^^^^^^^
  File "B:\Github\django-unchained\.venv\Lib\site-packages\rest_framework\settings.py", line 227, in __getattr__
    val = perform_import(val, attr)
  File "B:\Github\django-unchained\.venv\Lib\site-packages\rest_framework\settings.py", line 168, in perform_import
    return import_from_string(val, setting_name)
  File "B:\Github\django-unchained\.venv\Lib\site-packages\rest_framework\settings.py", line 182, in import_from_string
    raise ImportError(msg)
ImportError: Could not import 'api.resources.exception_handler.custom_exception_handler' for API setting 'EXCEPTION_HANDLER'. ModuleNotFoundError: No module named 'api.resources.exception_handler'.
ERROR 2025-07-04 03:15:31,885 exception_handler 4460 4916 <class 'rest_framework.exceptions.MethodNotAllowed'>: Method "PUT" not allowed.
ERROR 2025-07-04 03:15:31,903 log 4460 4916 Internal Server Error: /api/v1/email/signup/verification/
Traceback (most recent call last):
  File "B:\Github\django-unchained\.venv\Lib\site-packages\django\core\handlers\exception.py", line 55, in inner
    response = get_response(request)
  File "B:\Github\django-unchained\.venv\Lib\site-packages\django\core\handlers\base.py", line 197, in _get_response
    response = wrapped_callback(request, *callback_args, **callback_kwargs)
  File "B:\Github\django-unchained\.venv\Lib\site-packages\django\views\decorators\csrf.py", line 65, in _view_wrapper
    return view_func(request, *args, **kwargs)
  File "B:\Github\django-unchained\.venv\Lib\site-packages\django\views\generic\base.py", line 105, in view
    return self.dispatch(request, *args, **kwargs)
           ~~~~~~~~~~~~~^^^^^^^^^^^^^^^^^^^^^^^^^^
  File "B:\Github\django-unchained\.venv\Lib\site-packages\rest_framework\views.py", line 515, in dispatch
    response = self.handle_exception(exc)
  File "B:\Github\django-unchained\.venv\Lib\site-packages\rest_framework\views.py", line 475, in handle_exception
    self.raise_uncaught_exception(exc)
    ~~~~~~~~~~~~~~~~~~~~~~~~~~~~~^^^^^
  File "B:\Github\django-unchained\.venv\Lib\site-packages\rest_framework\views.py", line 486, in raise_uncaught_exception
    raise exc
  File "B:\Github\django-unchained\.venv\Lib\site-packages\rest_framework\views.py", line 512, in dispatch
    response = handler(request, *args, **kwargs)
  File "B:\Github\django-unchained\.venv\Lib\site-packages\rest_framework\views.py", line 173, in http_method_not_allowed
    raise exceptions.MethodNotAllowed(request.method)
rest_framework.exceptions.MethodNotAllowed: Method "PUT" not allowed.
ERROR 2025-07-04 14:59:48,594 exception_handler 17960 18128 <class 'rest_framework.exceptions.MethodNotAllowed'>: Method "PUT" not allowed.
ERROR 2025-07-04 14:59:48,632 log 17960 18128 Internal Server Error: /api/v1/email/signup/verification/
Traceback (most recent call last):
  File "B:\Github\django-unchained\.venv\Lib\site-packages\django\core\handlers\exception.py", line 55, in inner
    response = get_response(request)
  File "B:\Github\django-unchained\.venv\Lib\site-packages\django\core\handlers\base.py", line 197, in _get_response
    response = wrapped_callback(request, *callback_args, **callback_kwargs)
  File "B:\Github\django-unchained\.venv\Lib\site-packages\django\views\decorators\csrf.py", line 65, in _view_wrapper
    return view_func(request, *args, **kwargs)
  File "B:\Github\django-unchained\.venv\Lib\site-packages\django\views\generic\base.py", line 105, in view
    return self.dispatch(request, *args, **kwargs)
           ~~~~~~~~~~~~~^^^^^^^^^^^^^^^^^^^^^^^^^^
  File "B:\Github\django-unchained\.venv\Lib\site-packages\rest_framework\views.py", line 515, in dispatch
    response = self.handle_exception(exc)
  File "B:\Github\django-unchained\.venv\Lib\site-packages\rest_framework\views.py", line 475, in handle_exception
    self.raise_uncaught_exception(exc)
    ~~~~~~~~~~~~~~~~~~~~~~~~~~~~~^^^^^
  File "B:\Github\django-unchained\.venv\Lib\site-packages\rest_framework\views.py", line 486, in raise_uncaught_exception
    raise exc
  File "B:\Github\django-unchained\.venv\Lib\site-packages\rest_framework\views.py", line 512, in dispatch
    response = handler(request, *args, **kwargs)
  File "B:\Github\django-unchained\.venv\Lib\site-packages\rest_framework\views.py", line 173, in http_method_not_allowed
    raise exceptions.MethodNotAllowed(request.method)
rest_framework.exceptions.MethodNotAllowed: Method "PUT" not allowed.
ERROR 2025-07-04 15:09:02,364 exception_handler 10136 20344 <class 'rest_framework.exceptions.MethodNotAllowed'>: Method "PUT" not allowed.
ERROR 2025-07-04 15:09:02,401 log 10136 20344 Internal Server Error: /api/v1/email/signup/verification/
Traceback (most recent call last):
  File "B:\Github\django-unchained\.venv\Lib\site-packages\django\core\handlers\exception.py", line 55, in inner
    response = get_response(request)
  File "B:\Github\django-unchained\.venv\Lib\site-packages\django\core\handlers\base.py", line 197, in _get_response
    response = wrapped_callback(request, *callback_args, **callback_kwargs)
  File "B:\Github\django-unchained\.venv\Lib\site-packages\django\views\decorators\csrf.py", line 65, in _view_wrapper
    return view_func(request, *args, **kwargs)
  File "B:\Github\django-unchained\.venv\Lib\site-packages\django\views\generic\base.py", line 105, in view
    return self.dispatch(request, *args, **kwargs)
           ~~~~~~~~~~~~~^^^^^^^^^^^^^^^^^^^^^^^^^^
  File "B:\Github\django-unchained\.venv\Lib\site-packages\rest_framework\views.py", line 515, in dispatch
    response = self.handle_exception(exc)
  File "B:\Github\django-unchained\.venv\Lib\site-packages\rest_framework\views.py", line 475, in handle_exception
    self.raise_uncaught_exception(exc)
    ~~~~~~~~~~~~~~~~~~~~~~~~~~~~~^^^^^
  File "B:\Github\django-unchained\.venv\Lib\site-packages\rest_framework\views.py", line 486, in raise_uncaught_exception
    raise exc
  File "B:\Github\django-unchained\.venv\Lib\site-packages\rest_framework\views.py", line 512, in dispatch
    response = handler(request, *args, **kwargs)
  File "B:\Github\django-unchained\.venv\Lib\site-packages\rest_framework\views.py", line 173, in http_method_not_allowed
    raise exceptions.MethodNotAllowed(request.method)
rest_framework.exceptions.MethodNotAllowed: Method "PUT" not allowed.
ERROR 2025-07-04 15:09:22,884 exception_handler 2856 18700 <class 'rest_framework.exceptions.MethodNotAllowed'>: Method "PUT" not allowed.
ERROR 2025-07-04 15:09:22,909 log 2856 18700 Internal Server Error: /api/v1/email/signup/verification/
Traceback (most recent call last):
  File "B:\Github\django-unchained\.venv\Lib\site-packages\django\core\handlers\exception.py", line 55, in inner
    response = get_response(request)
  File "B:\Github\django-unchained\.venv\Lib\site-packages\django\core\handlers\base.py", line 197, in _get_response
    response = wrapped_callback(request, *callback_args, **callback_kwargs)
  File "B:\Github\django-unchained\.venv\Lib\site-packages\django\views\decorators\csrf.py", line 65, in _view_wrapper
    return view_func(request, *args, **kwargs)
  File "B:\Github\django-unchained\.venv\Lib\site-packages\django\views\generic\base.py", line 105, in view
    return self.dispatch(request, *args, **kwargs)
           ~~~~~~~~~~~~~^^^^^^^^^^^^^^^^^^^^^^^^^^
  File "B:\Github\django-unchained\.venv\Lib\site-packages\rest_framework\views.py", line 515, in dispatch
    response = self.handle_exception(exc)
  File "B:\Github\django-unchained\.venv\Lib\site-packages\rest_framework\views.py", line 475, in handle_exception
    self.raise_uncaught_exception(exc)
    ~~~~~~~~~~~~~~~~~~~~~~~~~~~~~^^^^^
  File "B:\Github\django-unchained\.venv\Lib\site-packages\rest_framework\views.py", line 486, in raise_uncaught_exception
    raise exc
  File "B:\Github\django-unchained\.venv\Lib\site-packages\rest_framework\views.py", line 512, in dispatch
    response = handler(request, *args, **kwargs)
  File "B:\Github\django-unchained\.venv\Lib\site-packages\rest_framework\views.py", line 173, in http_method_not_allowed
    raise exceptions.MethodNotAllowed(request.method)
rest_framework.exceptions.MethodNotAllowed: Method "PUT" not allowed.
ERROR 2025-07-04 15:12:45,116 exception_handler 15024 18312 <class 'rest_framework.exceptions.ValidationError'>: {'valid_till': [ErrorDetail(string='This field is required.', code='required')]}
ERROR 2025-07-04 15:12:45,116 exception_handler 15024 18312 Response data: {'valid_till': [ErrorDetail(string='This field is required.', code='required')]}
WARNING 2025-07-04 15:12:45,118 log 15024 18312 Bad Request: /api/v1/email/signup/verification/
ERROR 2025-07-04 15:57:42,141 exception_handler 10156 20360 <class 'AttributeError'>: 'Settings' object has no attribute 'EMAIL_VERIFICATION_LENGTH'
ERROR 2025-07-04 15:57:42,141 exception_handler 10156 20360 Response data: {'type': "<class 'AttributeError'>", 'action': '<api.resources.v1.email_verification.EmailVerificationCodeView object at 0x0000013B9343ACF0>', 'messages': ["'Settings' object has no attribute 'EMAIL_VERIFICATION_LENGTH'"], 'status': 500, 'error': True}
ERROR 2025-07-04 15:57:42,143 log 10156 20360 Internal Server Error: /api/v1/email/signup/verification/
ERROR 2025-07-04 16:10:20,290 exception_handler 19304 15320 <class 'django.db.utils.IntegrityError'>: null value in column "deleted_at" of relation "email_verification" violates not-null constraint
DETAIL:  Failing row contains (1, anonymous, anonymous, 2025-07-04 10:40:20.281274+00, 2025-07-04 10:40:20.281289+00, null, test001@test.com, UA7slHtcZPy4X8Tetf57DJPX6MEqN3cL, 2025-07-04 11:10:20.281036+00).

ERROR 2025-07-04 16:10:20,291 exception_handler 19304 15320 Response data: {'type': "<class 'django.db.utils.IntegrityError'>", 'action': '<api.resources.v1.email_verification.EmailVerificationCodeView object at 0x0000020A6E176CF0>', 'messages': ['null value in column "deleted_at" of relation "email_verification" violates not-null constraint\nDETAIL:  Failing row contains (1, anonymous, anonymous, 2025-07-04 10:40:20.281274+00, 2025-07-04 10:40:20.281289+00, null, test001@test.com, UA7slHtcZPy4X8Tetf57DJPX6MEqN3cL, 2025-07-04 11:10:20.281036+00).\n'], 'status': 500, 'error': True}
ERROR 2025-07-04 16:10:20,294 log 19304 15320 Internal Server Error: /api/v1/email/signup/verification/
ERROR 2025-07-04 16:24:57,056 exception_handler 2808 18848 <class 'django.db.utils.IntegrityError'>: null value in column "deleted_at" of relation "email_verification" violates not-null constraint
DETAIL:  Failing row contains (1, anonymous, anonymous, 2025-07-04 10:54:57.049738+00, 2025-07-04 10:54:57.049746+00, null, test001@test.com, CpuTb8RQSRFKNBEUi0uzWbWpVKfZ9wkY, 2025-07-04 11:24:57.049557+00).

ERROR 2025-07-04 16:24:57,057 exception_handler 2808 18848 Response data: {'type': "<class 'django.db.utils.IntegrityError'>", 'action': '<api.resources.v1.email_verification.EmailVerificationCodeView object at 0x000002065D71ECF0>', 'messages': ['null value in column "deleted_at" of relation "email_verification" violates not-null constraint\nDETAIL:  Failing row contains (1, anonymous, anonymous, 2025-07-04 10:54:57.049738+00, 2025-07-04 10:54:57.049746+00, null, test001@test.com, CpuTb8RQSRFKNBEUi0uzWbWpVKfZ9wkY, 2025-07-04 11:24:57.049557+00).\n'], 'status': 500, 'error': True}
ERROR 2025-07-04 16:24:57,058 log 2808 18848 Internal Server Error: /api/v1/email/signup/verification/
ERROR 2025-07-04 16:26:44,898 exception_handler 18600 7084 <class 'django.db.utils.IntegrityError'>: null value in column "deleted_at" of relation "email_verification" violates not-null constraint
DETAIL:  Failing row contains (1, anonymous, anonymous, 2025-07-04 10:56:44.896017+00, 2025-07-04 10:56:44.896028+00, null, test001@test.com, 2QVaJUWpuRVmjhF8Z2B7VUe1ObWhTfK2, 2025-07-04 11:26:44.895779+00).

ERROR 2025-07-04 16:26:44,898 exception_handler 18600 7084 Response data: {'type': "<class 'django.db.utils.IntegrityError'>", 'action': '<api.resources.v1.email_verification.EmailVerificationCodeView object at 0x000001E2D100ACF0>', 'messages': ['null value in column "deleted_at" of relation "email_verification" violates not-null constraint\nDETAIL:  Failing row contains (1, anonymous, anonymous, 2025-07-04 10:56:44.896017+00, 2025-07-04 10:56:44.896028+00, null, test001@test.com, 2QVaJUWpuRVmjhF8Z2B7VUe1ObWhTfK2, 2025-07-04 11:26:44.895779+00).\n'], 'status': 500, 'error': True}
ERROR 2025-07-04 16:26:44,900 log 18600 7084 Internal Server Error: /api/v1/email/signup/verification/
ERROR 2025-07-04 16:28:33,946 exception_handler 20720 17656 <class 'rest_framework.exceptions.ValidationError'>: {'valid_till': [ErrorDetail(string='This field is required.', code='required')]}
ERROR 2025-07-04 16:28:33,946 exception_handler 20720 17656 Response data: {'valid_till': [ErrorDetail(string='This field is required.', code='required')]}
WARNING 2025-07-04 16:28:33,947 log 20720 17656 Bad Request: /api/v1/email/signup/verification/
ERROR 2025-07-04 17:13:47,445 exception_handler 21244 18948 <class 'rest_framework.exceptions.ValidationError'>: {'valid_till': [ErrorDetail(string='This field is required.', code='required')]}
ERROR 2025-07-04 17:13:47,445 exception_handler 21244 18948 Response data: {'valid_till': [ErrorDetail(string='This field is required.', code='required')]}
WARNING 2025-07-04 17:13:47,446 log 21244 18948 Bad Request: /api/v1/email/signup/verification/
